# NEXUSMIND 故障排查日志

本文档用于记录和系统性地排查在开发和测试过程中遇到的问题。
 
---

## 2025-07-03: CI `ModuleNotFoundError`

**问题描述:**
CI/CD 流水线中的 `pytest` 步骤失败，报告 `ModuleNotFoundError: No module named 'core.nexusmind.storage.s3_storage'`。此问题在本地环境中可能因不健壮的 `sys.path.insert` 路径修改而未被发现。

**根本原因分析:**
项目采用了非标准的 `core/` 目录结构，依赖于不稳定的路径修改技巧来工作，导致在不同环境（本地 vs CI）下的行为不一致。

**解决方案:**
采纳 Python 社区的最佳实践，将项目重构为标准的 `src` 布局，从根本上解决路径发现问题。

### **执行计划**

#### **第一步：创建 `src` 目录并移动源代码**

**操作:**
将 `core/nexusmind` 源代码目录移动到新的 `src/nexusmind` 位置，并清理旧的目录结构。这被视为重构的第一阶段。

**反馈:**
* **2025-07-03**: 已执行。源代码已移动到 `src/` 目录下。

#### **第二步：更新 `pyproject.toml` 以识别新布局**

**操作:**
修改 `pyproject.toml`，告知 Poetry 新的 `src` 布局。

**反馈:**
* **2025-07-03**: 已执行。`poetry check` 通过。

#### **第三步：移除所有测试文件中的路径修改代码 (关键步骤)**

**操作:**
遍历所有测试文件，删除不健壮的 `sys.path.insert()` 路径修改代码。

**反馈:**
* **2025-07-03**: 待执行。

#### **第四步：修正 `src/nexusmind/` 目录内部所有文件之间的相互导入语句**

**操作:**
由于 `sys.path` 已被移除，现在需要修正 `src/nexusmind/` 目录内部所有文件之间的相互导入语句，将所有 `from core.nexusmind...` 替换为正确的相对或绝对导入。

**反馈:**
* **2025-07-03**: 已修复 `src/nexusmind/celery_app.py`。`pytest` 错误链深入一层，暴露了 `src/nexusmind/config.py` 中的新导入问题。
* **2025-07-03**: 已修复 `src/nexusmind/config.py` 的相对导入路径。新暴露的问题是 `ImportError`，表明 `base_config.py` 文件中缺少 `MinioConfig` 等类的定义。
* **2025-07-03**: 已在 `src/nexusmind/base_config.py` 中添加缺失的配置类。新的导入瓶颈转移到了项目根目录的 `main.py` 文件。
* **2025-07-03**: 已修复 `main.py` 中的所有导入语句。`pytest` 错误链继续深入，暴露出 `src/nexusmind/brain/brain.py` 的导入问题。
* **2025-07-03**: 已修复 `brain.py` 中对 `llm_endpoint` 的导入。下一个待修复的导入在同一个文件内：`logger`。
* **2025-07-03**: 已修复 `brain.py` 中对 `logger` 的相对路径导入。新暴露的问题是 `ImportError`，表明 `logger.py` 文件中缺少 `get_logger` 函数的定义。
* **2025-07-03**: 已在 `logger.py` 中添加 `get_logger` 函数。`pytest` 错误链继续深入，暴露了 `storage/faiss_vector_store.py` 中的导入问题。
* **2025-07-03**: 已修复 `faiss_vector_store.py` 的导入。新的 `ModuleNotFoundError` 暴露在其基类 `vector_store_base.py` 中。
* **2025-07-03**: 已修复 `vector_store_base.py` 的导入。错误链回跳，暴露出 `brain.py` 中存在一个遗漏的、未被修复的旧式导入。
* **2025-07-03**: 已彻底修复 `brain.py` 的所有导入。`test_api.py` 的 `ModuleNotFoundError` 已解决，新问题为 `ImportError`，因 `config.py` 缺少 `get_core_config` 函数。
* **2025-07-03**: 已修复 `config.py` 中 `get_core_config` 函数缺失的问题。
* **2025-07-03**: 已修复 `tests/test_brain.py` 中的 `IndentationError`。
* **2025-07-03**: 已修复 `tests/test_nexus_file.py` 的导入问题并移除空测试。
* **2025-07-03**: 已修复 `tests/test_config.py` 的 `NameError: name 'os' is not defined` 问题。
* **2025-07-03**: 已修复 `src/nexusmind/database.py` 的导入问题。
* **2025-07-03**: 已修复 `src/nexusmind/processor/implementations/simple_txt_processor.py` 的导入问题。
* **2025-07-03**: 已修复 `src/nexusmind/processor/processor_base.py` 的导入问题，此举暴露了 `registry.py` 的导入错误。
* **2025-07-03**: 已修复 `src/nexusmind/processor/registry.py` 的导入。`tests/processor/test_registry.py` 的错误类型转变为 `ImportError`，因缺少 `get_processor_registry` 函数。同时，`test_api.py` 的错误链指向 `nexus_rag.py`。
* **2025-07-03**: 已在 `registry.py` 中添加 `get_processor_registry` 函数。`test_registry.py` 的错误转移为 `ImportError`，因其试图导入一个不存在的 `register_processor` 函数。
* **2025-07-03**: 已修复 `tests/processor/test_registry.py` 的导入逻辑错误。`pytest` 错误总数减少至 6 个。
* **2025-07-03**: 已修复 `src/nexusmind/rag/nexus_rag.py` 的导入问题。`test_api.py` 的错误链深入，暴露出 `s3_storage.py` 模块丢失的问题。
* **2025-07-03**: 已重新创建并补全 `src/nexusmind/storage/s3_storage.py` 文件。
* **2025-07-03**: 已修复 `src/nexusmind/tasks.py` 的导入问题。`test_api.py` 的错误类型转变为 `ImportError`，因 `main.py` 试图导入一个不存在的 `process_file_task` 函数。
* **2025-07-03**: 已修复 `main.py` 中的导入命名错误。`tests/test_api.py` 的收集时错误已完全解决，`pytest` 错误总数减少至 5 个。
* **2025-07-03**: 已修复 `src/nexusmind/brain/serialization.py` 的导入问题。此举并未完全解决 `brain` 相关的错误，`test_brain.py` 的错误转移为 `ImportError`，因缺少 `BrainVector` 定义。
* **2025-07-03**: 经调查 `06_BRAIN.md`，确认 `BrainVector` 和 `serialize_brain` 并非原始设计的一部分，根源是 `tests/test_brain.py` 的导入和逻辑与实现脱节。
* **2025-07-03**: 已彻底修正 `tests/test_brain.py` 的导入和内部逻辑，并清除了 `serialization.py` 中冗余的代码。`pytest` 错误总数减少至 4 个。
* **2025-07-03**: 已修复 `tests/test_nexus_rag.py` 的导入问题，`pytest` 错误总数减少至 3 个。
* **2025-07-03**: 已修复 `src/nexusmind/storage/local_storage.py` 的导入问题。`test_storage.py` 的收集错误已解决，`pytest` 错误总数减少至 2 个。
* **2025-07-03**: 已修复 `tests/test_vector_store.py` 的导入问题。`pytest` 错误总数减少至 1 个。

---

## 2025-07-05: 从干净状态恢复

### **执行计划**

#### **第一步：修复 `ModuleNotFoundError: No module named 'nexusmind.storage.s3_storage'`**

**问题描述:**
在将代码库重置到一个干净的基线后，`pytest` 报告了 2 个收集时错误。两个错误均由 `ModuleNotFoundError: No module named 'nexusmind.storage.s3_storage'` 引发。

**根本原因分析:**
`git reset` 操作将项目恢复到了一个 `src/nexusmind/storage/s3_storage.py` 文件还未被创建的时间点。由于 `main.py` 和 `tests/test_storage.py` 都依赖于导入这个文件，因此文件的缺失导致了致命的 `ModuleNotFoundError`，中断了测试的收集过程。

**解决方案:**
重新创建 `src/nexusmind/storage/s3_storage.py` 文件，并根据项目的设计文档（`docs/11_PROD_DATA_STORE.md`）为其添加必要的 `S3Storage` 类和 `get_s3_storage` 函数的骨架。

**反馈:**
* **2025-07-05**: 已修复。此举成功解决了所有 `pytest` 收集时错误，使我们能够进入运行时错误的修复阶段。

#### **第二步：修复 `tests/test_llm_endpoint.py` 中的 `NameError`**

**问题描述:**
`pytest` 报告在 `tests/test_llm_endpoint.py` 中有 3 个测试在设置阶段就因 `NameError: name 'CoreConfig' is not defined` 而失败。

**根本原因分析:**
该测试文件中的 `core_config` fixture 直接使用了 `CoreConfig` 类来创建一个实例，但文件顶部忘记了从 `nexusmind.config` 中导入这个类。

**解决方案:**
在 `tests/test_llm_endpoint.py` 文件顶部添加 `from nexusmind.config import CoreConfig`。

**反馈:**
* **2025-07-05**: 已修复。此举成功解决了 `tests/test_llm_endpoint.py` 中的 3 个 `ERROR`，`pytest` 的失败总数减少至 5 个。

#### **第三步：修复 `mock.patch` 中的 `ModuleNotFoundError`**

**问题描述:**
`tests/test_api.py` 中的 `test_async_upload_and_chat` 测试因 `ModuleNotFoundError: No module named 'core'` 而失败。

**根本原因分析:**
该测试内部使用了 `mock.patch('core.nexusmind.llm.llm_endpoint.litellm')`。`mock.patch` 使用的是字符串形式的路径，它不会被开发工具自动重构。在我们将 `core/` 目录重命名为 `src/` 后，这个硬编码的字符串路径没有被更新，导致了错误。

**解决方案:**
将 `mock.patch` 的字符串参数从 `core.nexusmind...` 修改为 `nexusmind...`。

**反馈:**
* **2025-07-05**: 已修复。此举成功解决了 `test_api.py` 中的 `ModuleNotFoundError`，并将故障点推进到了 `main.py` 中的依赖注入环节。

#### **第四步：修复 `S3Storage` 初始化时的 `TypeError`**

**问题描述:**
`tests/test_api.py` 的失败原因转变为 `TypeError: S3Storage.__init__() missing 1 required positional argument: 'config'`。

**根本原因分析:**
错误发生在 FastAPI 的依赖注入环节。`main.py` 中的 `get_s3_storage` 依赖提供者在调用 `S3Storage()` 时没有传递所需的 `config` 参数。

**解决方案:**
重构 `main.py` 中的 `get_s3_storage` 函数，让它依赖于 `get_core_config` 来获取配置实例，并将其作为参数传递给 `S3Storage` 的构造函数。

**反馈:**
* **2025-07-05**: 已修复。此举暴露了更深层次的问题：`TypeError: unhashable type: 'CoreConfig'`。原因是 `@lru_cache` 无法缓存以可变对象（如 Pydantic 模型）为参数的函数。

---

## 2025-07-05: 修复运行时 (Runtime) 错误 (续)

### **执行计划**

#### **第七步：修复 `test_config.py` 中的 `AssertionError`**

**问题描述:**
`tests/test_config.py` 中的 `test_init_without_override` 测试失败，断言 `'gpt-4' == 'gpt-4o'`。

**根本原因分析:**
`src/nexusmind/base_config.py` 中 `CoreConfig` 的默认模型 `llm_model_name` 被硬编码为 "gpt-4"，而测试用例期望的默认值是 "gpt-4o"。这是代码实现与测试期望之间的直接冲突。

**解决方案:**
以测试为准，将 `src/nexusmind/config.py` 中的默认模型修改为 `gpt-4o`，并将默认 `temperature` 修改为 `0.7` 以匹配测试期望。

**反馈:**
* **2025-07-05**: 已修复 `llm_model_name` 的断言错误，但新暴露出 `temperature` 的断言错误 (`assert 0.5 == 0.7`)。修复仍在进行中。

#### **第八步：移除不当的缓存**

**问题描述:**
`
---

## 2025-07-06: 修复运行时 (Runtime) 错误 (续)

**问题描述:**
在修正了 `.gitignore` 问题并能正确追踪 `s3_storage.py` 文件后，`pytest` 现在可以运行，但报告了 4 个新的运行时错误。

**初步分析:**
当前的 4 个失败是：
1.  `tests/test_api.py::test_async_upload_and_chat`: `TypeError: unhashable type: 'CoreConfig'` - 这通常由缓存函数（如使用 `@lru_cache`）试图处理一个不可哈希的（可变）参数（如 Pydantic 配置对象）引起。
2.  `tests/test_brain.py::test_save_and_load_brain`: `ModuleNotFoundError: No module named 'core'` - 在 `brain.py` 中存在一个指向旧 `core/` 目录结构的绝对导入语句，是代码重构的遗留问题。
3.  `tests/test_llm_endpoint.py::test_get_chat_completion`: `NameError: name 'Mock' is not defined` - 测试文件中使用了 `Mock` 对象但忘记导入。
4.  `tests/test_vector_store.py::test_add_and_search`: `NameError: name 'logger' is not defined` - 在 `faiss_vector_store.py` 文件中使用了 `logger` 但未定义。

### **执行计划**

#### **第一步：修复 `brain.py` 中的 `ModuleNotFoundError`**

**问题:**
`tests/test_brain.py` 测试失败，因为 `src/nexusmind/brain/brain.py` 在其 `save` 方法中使用了过时的导入路径: `from core.nexusmind.brain import serialization`。

**根本原因分析:**
这是从 `core/` 到 `src/` 目录结构重构时遗漏的硬编码路径。

**解决方案:**
将 `src/nexusmind/brain/brain.py` 中的绝对导入更改为相对导入：`from . import serialization`。

**反馈:**
* **2025-07-06**: 已修复。此举成功解决了 `ModuleNotFoundError`，但暴露了更深层次的 `AttributeError`，因为 `brain.py` 中调用的函数 `save_brain_to_file` 在 `serialization.py` 模块中不存在。

#### **第二步：修复 `brain.py` 中的 `AttributeError`**

**问题:**
`tests/test_brain.py` 测试失败，因为 `brain.py` 试图调用一个不存在的函数 `serialization.save_brain_to_file(self)`。

**根本原因分析:**
上一步的修复中，对 `save_brain_to_file` 的调用是一个不正确的猜测。我们需要检查 `serialization.py` 文件的实际内容，以确定正确的函数名称和签名。

**解决方案:**
检查 `src/nexusmind/brain/serialization.py` 的内容，并相应地更正 `src/nexusmind/brain/brain.py` 中的函数调用。

**反馈:**
* **2025-07-06**: 已修复。此举成功解决了 `AttributeError`，但错误链沿着调用栈深入，暴露出 `faiss_vector_store.py` 中存在 `NameError`，因其缺少 `logger` 的定义。

#### **第三步：修复 `faiss_vector_store.py` 中的 `NameError`**

**问题:**
`test_save_and_load_brain` 测试因 `NameError: name 'logger' is not defined` 而失败。

**根本原因分析:**
在 `save_brain` 的执行过程中，会调用 `vector_store.save_to_disk()`。`faiss_vector_store.py` 文件中的 `save_to_disk` 方法使用了 `logger` 对象，但在文件作用域内并未定义它。

**解决方案:**
在 `src/nexusmind/storage/faiss_vector_store.py` 文件顶部添加标准的日志记录器设置 (`import logging` 和 `logger = logging.getLogger(__name__)`)。

**反馈:**
* **2025-07-06**: 已修复。`tests/test_brain.py` 中的所有测试现已通过。

#### **第四步：修复 `test_llm_endpoint.py` 中的 `NameError`**

**问题:**
`tests/test_llm_endpoint.py` 中的 `test_get_chat_completion` 测试因 `NameError: name 'Mock' is not defined` 而失败。

**根本原因分析:**
该测试文件使用了 `Mock` 对象，但忘记了从 `unittest.mock` 中导入它。

**解决方案:**
在 `tests/test_llm_endpoint.py` 文件顶部添加 `from unittest.mock import Mock, patch`。

**反馈:**
* **2025-07-06**: 已修复。`tests/test_llm_endpoint.py` 中的所有测试现已通过。

#### **第五步：修复 `test_api.py` 中的 `TypeError`**

**问题:**
在 `tests/test_api.py` 中，端到端测试 `test_async_upload_and_chat` 因 `TypeError: unhashable type: 'CoreConfig'` 而失败。

**根本原因分析:**
这个错误是由于某个被 `@lru_cache` 装饰的函数试图缓存一个以 `CoreConfig` 对象为参数的调用而引起的。Pydantic 模型（如 `CoreConfig`）是可变对象，因此不可哈希，不能被用作缓存的键。错误发生在 FastAPI 的依赖注入过程中，说明问题出在某个作为依赖项提供给 API 路由的函数上。

**解决方案:**
找到这个被错误缓存的依赖项函数，并移除其 `@lru_cache` 装饰器。

**反馈:**
* **2025-07-06**: 移除了 `src/nexusmind/config.py` 中 `get_core_config` 函数的缓存，但这并未解决问题，错误依旧。根本原因必定是 `main.py` 中的另一个依赖项函数被不当地缓存了。

#### **第六步：定位并修复 `main.py` 中不当的缓存**

**问题:**
`test_api.py` 中的 `TypeError` 在上一步修复后仍然存在。

**根本原因分析:**
通过 `grep` 搜索发现，在 `main.py` 中也存在 `@lru_cache` 的使用。错误追踪信息表明，问题发生在 FastAPI 的依赖注入过程中，当它试图为 API 端点解析依赖时。这强烈暗示 `main.py` 中某个被缓存的依赖提供者函数（dependency provider）在其参数中接收了 `CoreConfig` 对象，导致了缓存失败。

**解决方案:**
检查 `main.py`，找到所有被 `@lru_cache` 装饰的、且依赖于 `CoreConfig` 的函数，并移除它们的缓存装饰器。

**反馈:**
* **2025-07-06**: 已修复。此举成功解决了 `TypeError`，但暴露了新的 `AttributeError: 'CoreConfig' object has no attribute 'access_key'`。

#### **第七步：修复 `S3Storage` 初始化时的 `AttributeError`**

**问题:**
`test_api.py` 测试失败，因为在初始化 `S3Storage` 时，`CoreConfig` 对象上缺少 `access_key` 属性。

**根本原因分析:**
在 `main.py` 的 `get_s3_storage` 依赖提供者中，我们将整个 `CoreConfig` 实例传递给了 `S3Storage`。而 `S3Storage` 的构造函数试图直接从这个 `CoreConfig` 实例中访问 S3 相关的配置（如 `access_key`），但这些配置实际上是嵌套在 `config.minio` 这个 `MinioConfig` 对象中的。

**解决方案:**
1.  修改 `main.py` 中的 `get_s3_storage` 函数，使其在调用 `S3Storage` 时，传递正确的、嵌套的配置对象 `config.minio`。
2.  修改 `src/nexusmind/storage/s3_storage.py` 中 `S3Storage` 的构造函数，明确其接收的参数类型是 `MinioConfig`。

**反馈:**
* **2025-07-06**: 待执行。
